Workbook

Sheet Client PL
A1: ID | B1: Client Name | C1: 2024 | AM1: 2025
C2: Jan | F2: Feb | I2: Mar | L2: Apr | O2: Mei | R2: Jun | U2: Jul | X2: Aug | AA2: Sep | AD2: Okt | AG2: Nov | AJ2: Des | AM2: Jan | AQ2: Feb | AU2: Mar | AY2: Apr | BC2: Mei | BG2: Jun | BK2: Jul | BO2: Aug | BS2: Sep | BW2: Oct | CA2: Nov | CE2: Dec | CI2: MTD Jan Until 11 Jan 2026 | CM2: Forecast Jan | CQ2: Increase/Decrease since last month | CR2: Note
C3: GMV | D3: Courier Cost | E3: Revenue | F3: GMV | G3: Courier Cost | H3: Revenue | I3: GMV | J3: Courier Cost | K3: Revenue | L3: GMV | M3: Courier Cost | N3: Revenue | O3: GMV | P3: Courier Cost | Q3: Revenue | R3: GMV | S3: Courier Cost | T3: Revenue | U3: GMV | V3: Courier Cost | W3: Revenue | X3: GMV | Y3: Courier Cost | Z3: Revenue | AA3: GMV | AB3: Courier Cost | AC3: Revenue | AD3: GMV | AE3: Courier Cost | AF3: Revenue | AG3: GMV | AH3: Courier Cost | AI3: Revenue | AJ3: GMV | AK3: Courier Cost | AL3: Revenue | AM3: Deliveries | AN3: GMV | AO3: Courier Cost | AP3: Revenue | AQ3: Deliveries | AR3: GMV | AS3: Courier Cost | AT3: Revenue | AU3: Deliveries | AV3: GMV | AW3: Courier Cost | AX3: Revenue | AY3: Deliveries | AZ3: GMV | BA3: Courier Cost | BB3: Revenue | BC3: Deliveries | BD3: GMV | BE3: Courier Cost | BF3: Revenue | BG3: Deliveries | BH3: GMV | BI3: Courier Cost | BJ3: Revenue | BK3: Deliveries | BL3: GMV | BM3: Courier Cost | BN3: Revenue | BO3: Deliveries | BP3: GMV | BQ3: Courier Cost | BR3: Revenue | BS3: Deliveries | BT3: GMV | BU3: Courier Cost | BV3: Revenue | BW3: Deliveries | BX3: GMV | BY3: Courier Cost | BZ3: Revenue | CA3: Deliveries | CB3: GMV | CC3: Courier Cost | CD3: Revenue | CE3: Deliveries | CF3: GMV | CG3: Courier Cost | CH3: Revenue | CI3: Deliveries | CJ3: GMV | CK3: Courier Cost | CL3: Revenue | CM3: Deliveries | CN3: GMV | CO3: Courier Cost | CP3: Revenue
A4: 843149 | B4: Halodoc Indonesia | C4: 1219244500 | D4: =C4-E4 | E4: 165429800 | F4: 361163600 | G4: =F4-H4 | H4: 55900800 | I4: 353249700 | J4: =I4-K4 | K4: 54976200 | L4: 165281900 | M4: =L4-N4 | N4: 28091200 | O4: 208407500 | P4: =O4-Q4 | Q4: 33177100 | R4: 248441000 | S4: =R4-T4 | T4: 48310600 | U4: 408460300 | V4: =U4-W4 | W4: 83162600 | X4: 461857000 | Y4: =X4-Z4 | Z4: 94120700 | AA4: 462978500 | AB4: =AA4-AC4 | AC4: 94073600 | AD4: 417571600 | AE4: =AD4-AF4 | AF4: 85267300 | AG4: 351527200 | AH4: =AG4-AI4 | AI4: 71838000 | AJ4: 351150000 | AK4: =AJ4-AL4 | AL4: 71848500 | AM4: 29536 | AN4: 295957629 | AO4: =AN4-AP4 | AP4: 61085700 | AQ4: 32137 | AR4: 325111100 | AS4: =AR4-AT4 | AT4: 66337700 | AU4: 31691 | AV4: 349759278 | AW4: =AV4-AX4 | AX4: 72212500 | AY4: 27655 | AZ4: 277367112 | BA4: =AZ4-BB4 | BB4: 57191400 | BC4: 28889 | BD4: 290251665 | BE4: =BD4-BF4 | BF4: 59931300 | BG4: 30508 | BH4: 306368568 | BI4: =BH4-BJ4 | BJ4: 63250100 | BK4: 33855 | BL4: 339804333 | BM4: =BL4-BN4 | BN4: 70176700 | BO4: 35020 | BP4: 351308331 | BQ4: =BP4-BR4 | BR4: 72485400 | BS4: 23895 | BT4: 266121702 | BU4: =BT4-BV4 | BV4: 54829400 | BW4: 15594 | BX4: 156339117 | BY4: =BX4-BZ4 | BZ4: 32140900 | CA4: 14312 | CB4: 144679600 | CC4: =CB4-CD4 | CD4: 29472200 | CE4: 13514 | CF4: 136482100 | CG4: 108648800 | CH4: =CF4-CG4 | CI4: 4715 | CJ4: 47601300 | CK4: 37913200 | CL4: 9688100 | CM4: =CI4/11*31 | CN4: =CJ4/11*31 | CO4: =CK4/11*31 | CP4: =CL4/11*31 | CQ4: =(CM4-CE4)/CE4
A5: 858126 | B5: Klean Katering Invoice | C5: 95370200 | D5: =C5-E5 | E5: 19051300 | F5: 74369700 | G5: =F5-H5 | H5: 14912000 | I5: 81022500 | J5: =I5-K5 | K5: 16241300 | L5: 76403100 | M5: =L5-N5 | N5: 15293000 | O5: 108232600 | P5: =O5-Q5 | Q5: 21679100 | R5: 96217800 | S5: =R5-T5 | T5: 19275100 | U5: 113835600 | V5: =U5-W5 | W5: 22837100 | X5: 112453000 | Y5: =X5-Z5 | Z5: 22551400 | AA5: 103305000 | AB5: =AA5-AC5 | AC5: 20729100 | AD5: 111846000 | AE5: =AD5-AF5 | AF5: 22421400 | AG5: 102442200 | AH5: =AG5-AI5 | AI5: 20557800 | AJ5: 75374200 | AK5: =AJ5-AL5 | AL5: 15281200 | AM5: 5533 | AN5: 88718000 | AO5: =AN5-AP5 | AP5: 17821500 | AQ5: 7032 | AR5: 111826700 | AS5: =AR5-AT5 | AT5: 22420300 | AU5: 6895 | AV5: 109306000 | AW5: =AV5-AX5 | AX5: 21864400 | AY5: 6930 | AZ5: 111417000 | BA5: =AZ5-BB5 | BB5: 22283400 | BC5: 7161 | BD5: 116559500 | BE5: =BD5-BF5 | BF5: 23322500 | BG5: 5592 | BH5: 91068000 | BI5: =BH5-BJ5 | BJ5: 18213600 | BK5: 6053 | BL5: 100396000 | BM5: =BL5-BN5 | BN5: 20086000 | BO5: 5808 | BP5: 95147000 | BQ5: =BP5-BR5 | BR5: 19032200 | BS5: 4439 | BT5: 82218000 | BU5: =BT5-BV5 | BV5: 16535400 | BW5: 5348 | BX5: 86171000 | BY5: =BX5-BZ5 | BZ5: 17234200 | CA5: 4064 | CB5: 67368500 | CC5: =CB5-CD5 | CD5: 13473700 | CE5: 3442 | CF5: 58137000 | CG5: 46509600 | CH5: =CF5-CG5 | CI5: 1057 | CJ5: 17905000 | CK5: 14324000 | CL5: 3581000 | CM5: =CI5/11*31 | CN5: =CJ5/11*31 | CO5: =CK5/11*31 | CP5: =CL5/11*31 | CQ5: =(CM5-CE5)/CE5 | CR5: Starting to have marketing campaign on next week.
A6: 220980 | B6: DSV | C6: 49050400 | D6: =C6-E6 | E6: 9814300 | F6: 48963200 | G6: =F6-H6 | H6: 9796500 | I6: 48894100 | J6: =I6-K6 | K6: 9783100 | L6: 48891600 | M6: =L6-N6 | N6: 9776200 | O6: 48892400 | P6: =O6-Q6 | Q6: 9776300 | R6: 48886100 | S6: =R6-T6 | T6: 9781100 | U6: 48881300 | V6: =U6-W6 | W6: 9779300 | X6: 48923600 | Y6: =X6-Z6 | Z6: 9794600 | AA6: 49021300 | AB6: =AA6-AC6 | AC6: 9802300 | AD6: 48877300 | AE6: =AD6-AF6 | AF6: 9777300 | AG6: 48893500 | AH6: =AG6-AI6 | AI6: 9781100 | AJ6: 48613500 | AK6: =AJ6-AL6 | AL6: 9725100 | AM6: 9 | AN6: 58592709 | AO6: =AN6-AP6 | AP6: 9748000 | AQ6: 9 | AR6: 59251044 | AS6: =AR6-AT6 | AT6: 9871600 | AU6: 9 | AV6: 59251044 | AW6: =AV6-AX6 | AX6: 9806100 | AY6: 9 | AZ6: 59251044 | BA6: =AZ6-BB6 | BB6: 9806000 | BC6: 10 | BD6: 63533774 | BE6: =BD6-BF6 | BF6: 10605300 | BG6: 10 | BH6: 65510419 | BI6: =BH6-BJ6 | BJ6: 10972500 | BK6: 10 | BL6: 65510419 | BM6: =BL6-BN6 | BN6: 10920700 | BO6: 10 | BP6: 65510419 | BQ6: =BP6-BR6 | BR6: 14728200 | BS6: 10 | BT6: 65510419 | BU6: =BT6-BV6 | BV6: 10973700 | BW6: 10 | BX6: 65510419 | BY6: =BX6-BZ6 | BZ6: 15331800 | CA6: 9 | CB6: 58779200 | CC6: =CB6-CD6 | CD6: 14425900 | CE6: 9 | CF6: 58779200 | CG6: =34139400+9499600 | CH6: =CF6-CG6 | CI6: 9 | CJ6: =13147100+3565200 | CK6: =10519000+2850000 | CL6: =2628100+715200 | CM6: 9 | CN6: =CJ6/11*31 | CO6: =CK6/11*31 | CP6: =CL6/11*31 | CQ6: =(CM6-CE6)/CE6 | CR6: On February they will add 6 couriers
A7: 271536 | B7: Grouu Baby | C7: 111111300 | D7: =C7-E7 | E7: 23652000 | F7: 96541200 | G7: =F7-H7 | H7: 20729700 | I7: 101882500 | J7: =I7-K7 | K7: 22094800 | L7: 102375500 | M7: =L7-N7 | N7: 22809400 | O7: 106915300 | P7: =O7-Q7 | Q7: 23705600 | R7: 98958600 | S7: =R7-T7 | T7: 22375600 | U7: 96259600 | V7: =U7-W7 | W7: 21810800 | X7: 91228200 | Y7: =X7-Z7 | Z7: 20805900 | AA7: 79786500 | AB7: =AA7-AC7 | AC7: 18244200 | AD7: 83536500 | AE7: =AD7-AF7 | AF7: 19114000 | AG7: 81438100 | AH7: =AG7-AI7 | AI7: 18988800 | AJ7: 101751600 | AK7: =AJ7-AL7 | AL7: 21060600 | AM7: 2963 | AN7: 82436300 | AO7: =AN7-AP7 | AP7: 16644400 | AQ7: 2650 | AR7: 72354300 | AS7: =AR7-AT7 | AT7: 14577500 | AU7: 2937 | AV7: 80866200 | AW7: =AV7-AX7 | AX7: 16247000 | AY7: 2962 | AZ7: 85754500 | BA7: =AZ7-BB7 | BB7: 17212700 | BC7: 2777 | BD7: 80264000 | BE7: =BD7-BF7 | BF7: 16133200 | BG7: 2417 | BH7: 70415900 | BI7: =BH7-BJ7 | BJ7: 14182100 | BK7: 2767 | BL7: 76685700 | BM7: =BL7-BN7 | BN7: 15348300 | BO7: 2208 | BP7: 64488600 | BQ7: =BP7-BR7 | BR7: 12899800 | BS7: 1706 | BT7: 63495600 | BU7: =BT7-BV7 | BV7: 12677500 | BW7: 2107 | BX7: 61341400 | BY7: =BX7-BZ7 | BZ7: 12231600 | CA7: 1843 | CB7: 55618200 | CC7: =CB7-CD7 | CD7: 11169900 | CE7: 2202 | CF7: =67976400+30900 | CG7: =54374100+24600 | CH7: =CF7-CG7 | CI7: 524 | CJ7: =16364900+60800 | CK7: =13099600+48400 | CL7: =3265300+12400 | CM7: =CI7/11*31 | CN7: =CJ7/11*31 | CO7: =CK7/11*31 | CP7: =CL7/11*31 | CQ7: =(CM7-CE7)/CE7 | CR7: Decrease due to holiday
A8: 836197 | B8: Andalan Express Indonesia Invoice | C8: 33431200 | D8: =C8-E8 | E8: 7555200 | F8: 13785200 | G8: =F8-H8 | H8: 3355800 | I8: 19807300 | J8: =I8-K8 | K8: 4948000 | L8: 39405600 | M8: =L8-N8 | N8: 9804900 | O8: 58502500 | P8: =O8-Q8 | Q8: 14705100 | R8: 53755000 | S8: =R8-T8 | T8: 13600500 | U8: 49812700 | V8: =U8-W8 | W8: 12892100 | X8: 46878400 | Y8: =X8-Z8 | Z8: 12049900 | AA8: 45401500 | AB8: =AA8-AC8 | AC8: 11427300 | AD8: 44872900 | AE8: =AD8-AF8 | AF8: 11378200 | AG8: 65119700 | AH8: =AG8-AI8 | AI8: 17899900 | AJ8: 79845800 | AK8: =AJ8-AL8 | AL8: 21324400 | AM8: 2360 | AN8: 61318400 | AO8: =AN8-AP8 | AP8: 13488700 | AQ8: 337 | AR8: 9796000 | AS8: =AR8-AT8 | AT8: 2158800 | AU8: 1312 | AV8: 34691200 | AW8: =AV8-AX8 | AX8: 7650900 | AY8: 2558 | AZ8: 71511600 | BA8: =AZ8-BB8 | BB8: 14796200 | BC8: 2256 | BD8: 64088300 | BE8: =BD8-BF8 | BF8: 13215200 | BG8: 1723 | BH8: 53098300 | BI8: =BH8-BJ8 | BJ8: 10500200 | BK8: 1866 | BL8: 56212300 | BM8: =BL8-BN8 | BN8: 11380800 | BO8: 1814 | BP8: 56977800 | BQ8: =BP8-BR8 | BR8: 11402900 | BS8: 1452 | BT8: 57552300 | BU8: =BT8-BV8 | BV8: 11555300 | BW8: 1893 | BX8: 60246200 | BY8: =BX8-BZ8 | BZ8: 12222100 | CA8: 2178 | CB8: 70936900 | CC8: =CB8-CD8 | CD8: 14201300 | CE8: 2822 | CF8: 88983800 | CG8: 70644600 | CH8: =CF8-CG8 | CI8: 659 | CJ8: 19605400 | CK8: 15667400 | CL8: 3938000 | CM8: =CI8/11*31 | CN8: =CJ8/11*31 | CO8: =CK8/11*31 | CP8: =CL8/11*31 | CQ8: =(CM8-CE8)/CE8 | CR8: Decrease due to holiday
A9: 204616 | B9: Nuskin invoice | C9: 71032000 | D9: =C9-E9 | E9: 12714000 | F9: 60440000 | G9: =F9-H9 | H9: 11128000 | I9: 71356000 | J9: =I9-K9 | K9: 13490900 | L9: 82880000 | M9: =L9-N9 | N9: 15834000 | O9: 67746000 | P9: =O9-Q9 | Q9: 12864200 | R9: 60538000 | S9: =R9-T9 | T9: 11457600 | U9: 65180000 | V9: =U9-W9 | W9: 12336000 | X9: 68444000 | Y9: =X9-Z9 | Z9: 12888800 | AA9: 51432000 | AB9: =AA9-AC9 | AC9: 9661400 | AD9: 70482000 | AE9: =AD9-AF9 | AF9: 13321400 | AG9: 98847000 | AH9: =AG9-AI9 | AI9: 19069400 | AJ9: 96789000 | AK9: =AJ9-AL9 | AL9: 19257800 | AM9: 3131 | AN9: 92640400 | AO9: =AN9-AP9 | AP9: 18834100 | AQ9: 1793 | AR9: 55986000 | AS9: =AR9-AT9 | AT9: 10707600 | AU9: 1829 | AV9: 54794500 | AW9: =AV9-AX9 | AX9: 10546000 | AY9: 1756 | AZ9: 54494500 | BA9: =AZ9-BB9 | BB9: 10501200 | BC9: 2025 | BD9: 49992000 | BE9: =BD9-BF9 | BF9: 11082800 | BG9: 2198 | BH9: 64853000 | BI9: =BH9-BJ9 | BJ9: 12639000 | BK9: 1858 | BL9: 65861000 | BM9: =BL9-BN9 | BN9: 12904400 | BO9: 1789 | BP9: 59748000 | BQ9: =BP9-BR9 | BR9: 11758700 | BS9: 1565 | BT9: 50810500 | BU9: =BT9-BV9 | BV9: 10541800 | BW9: 1417 | BX9: 48003000 | BY9: =BX9-BZ9 | BZ9: 8942000 | CA9: 1547 | CB9: 56844000 | CC9: =CB9-CD9 | CD9: 11606200 | CE9: =1720+174 | CF9: 61079300 | CG9: =46065600+2228000 | CH9: =CF9-CG9 | CI9: =943+52 | CJ9: =27116000+940000 | CK9: =21692800+752000 | CL9: =5423200+188000 | CM9: =CI9/11*31 | CN9: =CJ9/11*31 | CO9: =CK9/11*31 | CP9: =CL9/11*31 | CQ9: =(CM9-CE9)/CE9 | CR9: Already start new year campaign
A10: 247209 | B10: mClinica Akun Utama | C10: 462141400 | D10: =C10-E10 | E10: 92449700 | F10: 488233100 | G10: =F10-H10 | H10: 97543000 | I10: 523832600 | J10: =I10-K10 | K10: 104644400 | L10: 458292900 | M10: =L10-N10 | N10: 91342600 | O10: 401958300 | P10: =O10-Q10 | Q10: 79968100 | R10: 351567800 | S10: =R10-T10 | T10: 70032300 | U10: 172330500 | V10: =U10-W10 | W10: 34365100 | X10: 200473700 | Y10: =X10-Z10 | Z10: 39830000 | AA10: 66145100 | AB10: =AA10-AC10 | AC10: 12521700 | AD10: 96198800 | AE10: =AD10-AF10 | AF10: 18386000 | AG10: 93112500 | AH10: =AG10-AI10 | AI10: 18020200 | AJ10: 97390900 | AK10: =AJ10-AL10 | AL10: 18518500 | AM10: 2674 | AN10: =76903000+15656100 | AO10: =AN10-AP10 | AP10: 17368300 | AQ10: 2464 | AR10: 83388200 | AS10: =AR10-AT10 | AT10: 15649600 | AU10: 2649 | AV10: 87999400 | AW10: =AV10-AX10 | AX10: 16615600 | AY10: 2847 | AZ10: 96675300 | BA10: =AZ10-BB10 | BB10: 18269900 | BC10: 2409 | BD10: 72119200 | BE10: =BD10-BF10 | BF10: 13951600 | BG10: 1498 | BH10: 37278600 | BI10: =BH10-BJ10 | BJ10: 7088400 | BK10: 1481 | BL10: 31524100 | BM10: =BL10-BN10 | BN10: 6003700 | BO10: 1469 | BP10: 31701600 | BQ10: =BP10-BR10 | BR10: 6064000 | BS10: 1272 | BT10: 33296000 | BU10: =BT10-BV10 | BV10: 6433600 | BW10: 1507 | BX10: 33246900 | BY10: =BX10-BZ10 | BZ10: 6403200 | CA10: 1387 | CB10: 30466800 | CC10: =CB10-CD10 | CD10: 5899200 | CE10: =1176+328 | CF10: =26336900+6777600 | CG10: =21069600+5649400 | CH10: =CF10-CG10 | CI10: 546 | CJ10: =9298800+2510900 | CK10: =7439600+2096000 | CL10: =1859200+414900 | CM10: =CI10/11*31 | CN10: =CJ10/11*31 | CO10: =CK10/11*31 | CP10: =CL10/11*31 | CQ10: =(CM10-CE10)/CE10 | CR10: They already start to testing our API
A11: 248484 | B11: PT. Cipta Dwiputra Cemerlang | C11: 18618300 | D11: =C11-E11 | E11: 2962000 | F11: 16417900 | G11: =F11-H11 | H11: 2624500 | I11: 18607200 | J11: =I11-K11 | K11: 2972500 | L11: 17992800 | M11: =L11-N11 | N11: 2881200 | O11: 21038700 | P11: =O11-Q11 | Q11: 3388700 | R11: 18706300 | S11: =R11-T11 | T11: 2997400 | U11: 23171400 | V11: =U11-W11 | W11: 4011600 | X11: 22668000 | Y11: =X11-Z11 | Z11: 4526700 | AA11: 23144000 | AB11: =AA11-AC11 | AC11: 4629400 | AD11: 23535900 | AE11: =AD11-AF11 | AF11: 4707600 | AG11: 23961300 | AH11: =AG11-AI11 | AI11: 4791800 | AJ11: 25026800 | AK11: =AJ11-AL11 | AL11: 5004900 | AM11: 2134 | AN11: 27010900 | AO11: =AN11-AP11 | AP11: 5402700 | AQ11: 1841 | AR11: 23212800 | AS11: =AR11-AT11 | AT11: 4643100 | AU11: 1893 | AV11: 23533100 | AW11: =AV11-AX11 | AX11: 4707900 | AY11: 2104 | AZ11: 26139900 | BA11: =AZ11-BB11 | BB11: 5229800 | BC11: 2106 | BD11: 26159900 | BE11: =BD11-BF11 | BF11: 5233800 | BG11: 1793 | BH11: 22193200 | BI11: =BH11-BJ11 | BJ11: 4440200 | BK11: 2156 | BL11: 26533200 | BM11: =BL11-BN11 | BN11: 5308700 | BO11: 2164 | BP11: 26608400 | BQ11: =BP11-BR11 | BR11: 5323600 | BS11: 1671 | BT11: 24686700 | BU11: =BT11-BV11 | BV11: 4938600 | BW11: 2297 | BX11: 28445700 | BY11: =BX11-BZ11 | BZ11: 5690800 | CA11: 1969 | CB11: 24389900 | CC11: =CB11-CD11 | CD11: 4879400 | CE11: 2308 | CF11: 28793200 | CG11: 23033100 | CH11: =CF11-CG11 | CI11: 660 | CJ11: 8250000 | CK11: 6599600 | CL11: 1650400 | CM11: =CI11/11*31 | CN11: =CJ11/11*31 | CO11: =CK11/11*31 | CP11: =CL11/11*31 | CQ11: =(CM11-CE11)/CE11 | CR11: Yesterday they mentioned that will be leave on 31 Jan due to efficiency and using own couriers (We're on process to talk with them)
A12: 212944 | B12: SSN | C12: 19726000 | D12: =C12-E12 | E12: 3947000 | F12: 16331400 | G12: =F12-H12 | H12: 3267600 | I12: 16762400 | J12: =I12-K12 | K12: 3353800 | L12: 11723700 | M12: =L12-N12 | N12: 2345700 | O12: 16829700 | P12: =O12-Q12 | Q12: 3330100 | R12: 16082200 | S12: =R12-T12 | T12: 3198200 | U12: 19740800 | V12: =U12-W12 | W12: 3949700 | X12: 17862400 | Y12: =X12-Z12 | Z12: 3574200 | AA12: 16904800 | AB12: =AA12-AC12 | AC12: 3382400 | AD12: 18978400 | AE12: =AD12-AF12 | AF12: 3797500 | AG12: 16480300 | AH12: =AG12-AI12 | AI12: 3297300 | AJ12: 14848900 | AK12: =AJ12-AL12 | AL12: 2971100 | AM12: 488 | AN12: 19094250 | AO12: =AN12-AP12 | AP12: 2969400 | AQ12: 556 | AR12: 21677000 | AS12: =AR12-AT12 | AT12: 3375700 | AU12: 566 | AV12: 24816250 | AW12: =AV12-AX12 | AX12: 3395200 | AY12: 514 | AZ12: 20618750 | BA12: =AZ12-BB12 | BB12: 3096500 | BC12: =493+44 | BD12: 21027750 | BE12: =BD12-BF12 | BF12: 3242700 | BG12: 563 | BH12: 21849750 | BI12: =BH12-BJ12 | BJ12: 3403700 | BK12: 632 | BL12: 24331750 | BM12: =BL12-BN12 | BN12: 3827500 | BO12: 558 | BP12: 22047250 | BQ12: =BP12-BR12 | BR12: 3380800 | BS12: 584 | BT12: 23747000 | BU12: =BT12-BV12 | BV12: 3592700 | BW12: =499+198 | BX12: 26532000 | BY12: =BX12-BZ12 | BZ12: 4133800 | CA12: 582 | CB12: 18396700 | CC12: =CB12-CD12 | CD12: 3680700 | CE12: 560 | CF12: 16911900 | CG12: 13528200 | CH12: =CF12-CG12 | CI12: 172 | CJ12: 5237200 | CK12: 4189200 | CL12: 1048000 | CM12: =CI12/11*31 | CN12: =CJ12/11*31 | CO12: =CK12/11*31 | CP12: =CL12/11*31 | CQ12: =(CM12-CE12)/CE12 | CR12: Decrease due to holiday
A13: 955298 | B13: Alpro | C13: 0 | D13: =C13-E13 | E13: 0 | F13: 0 | G13: =F13-H13 | H13: 0 | I13: 0 | J13: =I13-K13 | K13: 0 | L13: 0 | M13: =L13-N13 | N13: 0 | O13: 0 | P13: =O13-Q13 | Q13: 0 | R13: 0 | S13: =R13-T13 | T13: 0 | U13: 0 | V13: =U13-W13 | W13: 0 | X13: 0 | Y13: =X13-Z13 | Z13: 0 | AA13: 0 | AB13: =AA13-AC13 | AC13: 0 | AD13: 12500 | AE13: =AD13-AF13 | AF13: -1500 | AG13: 124400 | AH13: =AG13-AI13 | AI13: 17900 | AJ13: 22811500 | AK13: =AJ13-AL13 | AL13: 5061400 | AM13: 579 | AN13: 9279800 | AO13: =AN13-AP13 | AP13: 2012500 | AQ13: 435 | AR13: 7094200 | AS13: =AR13-AT13 | AT13: 1523700 | AU13: 527 | AV13: 8912700 | AW13: =AV13-AX13 | AX13: 1954900 | AY13: 580 | AZ13: 9368100 | BA13: =AZ13-BB13 | BB13: 2048800 | BC13: 802 | BD13: 14497900 | BE13: =BD13-BF13 | BF13: 3090100 | BG13: 954 | BH13: 15671800 | BI13: =BH13-BJ13 | BJ13: 3344100 | BK13: 1074 | BL13: 17989600 | BM13: =BL13-BN13 | BN13: 3801300 | BO13: 1343 | BP13: 22078900 | BQ13: =BP13-BR13 | BR13: 4680900 | BS13: 921 | BT13: 17649900 | BU13: =BT13-BV13 | BV13: 3747300 | BW13: 1436 | BX13: 22098800 | BY13: =BX13-BZ13 | BZ13: 4733000 | CA13: 1847 | CB13: 26988600 | CC13: =CB13-CD13 | CD13: 5730000 | CE13: 1999 | CF13: 29790700 | CG13: 23574600 | CH13: =CF13-CG13 | CI13: 634 | CJ13: 9131900 | CK13: 7201500 | CL13: 1930400 | CM13: =CI13/11*31 | CN13: =CJ13/11*31 | CO13: =CK13/11*31 | CP13: =CL13/11*31 | CQ13: =(CM13-CE13)/CE13 | CR13: Decrease due to holiday
A14: 238666, 286265, 322799, 792916 | B14: Cokro Group | C14: 59654500 | D14: =C14-E14 | E14: =C14*20.5% | F14: 55248300 | G14: =F14-H14 | H14: =F14*20.5% | I14: 52662300 | J14: =I14-K14 | K14: =I14*20.5% | L14: 53836800 | M14: =L14-N14 | N14: =L14*20.5% | O14: 56809500 | P14: =O14-Q14 | Q14: =O14*20.5% | R14: 52480200 | S14: =R14-T14 | T14: =R14*20.5% | U14: 53736100 | V14: =U14-W14 | W14: =U14*20.5% | X14: 49412400 | Y14: =X14-Z14 | Z14: =X14*20.5% | AA14: 42626300 | AB14: =AA14-AC14 | AC14: =AA14*20.5% | AD14: 39131000 | AE14: =AD14-AF14 | AF14: =AD14*20.5% | AG14: 29468700 | AH14: =AG14-AI14 | AI14: =AG14*20.5% | AJ14: 27378100 | AK14: =AJ14-AL14 | AL14: =AJ14*20.5% | AM14: =405+446+289+183 | AN14: 26583400 | AO14: =AN14-AP14 | AP14: 5453700 | AQ14: =171+229+449+348 | AR14: 23747300 | AS14: =AR14-AT14 | AT14: 4473300 | AU14: 1187 | AV14: 23124700 | AW14: =AV14-AX14 | AX14: 5607700 | AY14: =181+274+395+220 | AZ14: 19715000 | BA14: =AZ14-BB14 | BB14: 3775300 | BC14: 1038 | BD14: 19186400 | BE14: =BD14-BF14 | BF14: 4211600 | BG14: 1056 | BH14: 19224200 | BI14: =BH14-BJ14 | BJ14: 4136100 | BK14: =204+299+272+318 | BL14: 20019900 | BM14: =BL14-BN14 | BN14: 4030000 | BO14: 1025 | BP14: 18441200 | BQ14: =BP14-BR14 | BR14: 3839600 | BS14: 1123 | BT14: 20670300 | BU14: =BT14-BV14 | BV14: 4411300 | BW14: 1082 | BX14: 19881700 | BY14: =BX14-BZ14 | BZ14: 4340000 | CA14: =173+332+463+324 | CB14: 21944400 | CC14: =CB14-CD14 | CD14: 4678200 | CE14: =369+21+542+406+193 | CF14: =8793800+6165000+9035900+5232800+2197000 | CG14: =6990300+489100+7066300+4170600+1733500 | CH14: =CF14-CG14 | CI14: =63+120+171+145 | CJ14: =695900+1677100+2957800+3092900+93300 | CK14: =548400+1337700+2298000+2459400+74000 | CL14: =147500+339400+659800+633500+19300 | CM14: =CI14/11*31 | CN14: =CJ14/11*31 | CO14: =CK14/11*31 | CP14: =CL14/11*31 | CQ14: =(CM14-CE14)/CE14 | CR14: Decrease due to holiday
A15: 250720 | B15: Selectro | C15: 16830500 | D15: =C15-E15 | E15: 4158700 | F15: 15099500 | G15: =F15-H15 | H15: 3700400 | I15: 14850300 | J15: =I15-K15 | K15: 3721900 | L15: 11873800 | M15: =L15-N15 | N15: 2878500 | O15: 15130300 | P15: =O15-Q15 | Q15: 3886200 | R15: 13493000 | S15: =R15-T15 | T15: 3555500 | U15: 15147300 | V15: =U15-W15 | W15: 4015500 | X15: 17139500 | Y15: =X15-Z15 | Z15: 4553500 | AA15: 14099600 | AB15: =AA15-AC15 | AC15: 3723400 | AD15: 16599900 | AE15: =AD15-AF15 | AF15: 4557300 | AG15: 17153400 | AH15: =AG15-AI15 | AI15: 5020000 | AJ15: 18367800 | AK15: =AJ15-AL15 | AL15: 6185500 | AM15: =377+129 | AN15: 12470600 | AO15: =AN15-AP15 | AP15: 4471900 | AQ15: 479 | AR15: 11356800 | AS15: =AR15-AT15 | AT15: 4275100 | AU15: 431 | AV15: 10734800 | AW15: =AV15-AX15 | AX15: 3918800 | AY15: 310 | AZ15: 8451400 | BA15: =AZ15-BB15 | BB15: 3230200 | BC15: 597 | BD15: 16045400 | BE15: =BD15-BF15 | BF15: 5791500 | BG15: =587+231 | BH15: 21020500 | BI15: =BH15-BJ15 | BJ15: 7778400 | BK15: =781+354 | BL15: 29299300 | BM15: =BL15-BN15 | BN15: 9982200 | BO15: 1139 | BP15: 25657100 | BQ15: =BP15-BR15 | BR15: 5216500 | BS15: 992 | BT15: 21343900 | BU15: =BT15-BV15 | BV15: 3973100 | BW15: 956 | BX15: 19383100 | BY15: =BX15-BZ15 | BZ15: 3946100 | CA15: 773 | CB15: 16240400 | CC15: =CB15-CD15 | CD15: 3297200 | CE15: 612 | CF15: 13539700 | CG15: 10791500 | CH15: =CF15-CG15 | CI15: 248 | CJ15: 4748200 | CK15: 3784000 | CL15: 964200 | CM15: =CI15/11*31 | CN15: =CJ15/11*31 | CO15: =CK15/11*31 | CP15: =CL15/11*31 | CQ15: =(CM15-CE15)/CE15 | CR15: Starting back to normal after holiday
A16: 831633 | B16: Lazada Indonesia Invoice | C16: 86287503 | D16: =C16-E16 | E16: 21035603 | F16: 84245929 | G16: =F16-H16 | H16: 20747729 | I16: 95395990 | J16: =I16-K16 | K16: 23527390 | L16: 71272994 | M16: =L16-N16 | N16: 17561794 | O16: 74053501 | P16: =O16-Q16 | Q16: 17940201 | R16: 64179148 | S16: =R16-T16 | T16: 15576948 | U16: 63087885 | V16: =U16-W16 | W16: 15268685 | X16: 59397101 | Y16: =X16-Z16 | Z16: 14231801 | AA16: 49417888 | AB16: =AA16-AC16 | AC16: 11209188 | AD16: 70873001 | AE16: =AD16-AF16 | AF16: 15776201 | AG16: 67352142 | AH16: =AG16-AI16 | AI16: 15137742 | AJ16: 12485001 | AK16: =AJ16-AL16 | AL16: 2758401 | AM16: 2264 | AN16: 37198074 | AO16: =AN16-AP16 | AP16: 8472149 | AQ16: 2336 | AR16: 38225965 | AS16: =AR16-AT16 | AT16: 8695347 | AU16: 518 | AV16: 9331700 | AW16: =AV16-AX16 | AX16: 2042400 | AY16: 582 | AZ16: 9837300 | BA16: =AZ16-BB16 | BB16: 2145700 | BC16: 2627 | BD16: 42197083 | BE16: =BD16-BF16 | BF16: 9442725 | BG16: 1998 | BH16: 32103333 | BI16: =BH16-BJ16 | BJ16: 7164473 | BK16: 1674 | BL16: 26304304 | BM16: =BL16-BN16 | BN16: 5948170 | BO16: 1060 | BP16: 17199456 | BQ16: =BP16-BR16 | BR16: 3911988 | BS16: 827 | BT16: 17089408 | BU16: =BT16-BV16 | BV16: 3863927 | BW16: 757 | BX16: 12419612 | BY16: =BX16-BZ16 | BZ16: 2801119 | CA16: 660 | CB16: 10708132 | CC16: =CB16-CD16 | CD16: 2482732 | CE16: 322 | CF16: 5279341 | CG16: 4077700 | CH16: =CF16-CG16 | CI16: 19 | CJ16: 250231 | CK16: 186600 | CL16: 63631 | CM16: =CI16/11*31 | CN16: =CJ16/11*31 | CO16: =CK16/11*31 | CP16: =CL16/11*31 | CQ16: =(CM16-CE16)/CE16 | CR16: The volume keep droping, we're on process to have meeting regardings the volume.
B17: DHL
A18: 379712 | B18: Aliansi Wikrama Dana | C18: 14547300 | D18: =C18-E18 | E18: 3094000 | F18: 15529500 | G18: =F18-H18 | H18: 3481300 | I18: 22663400 | J18: =I18-K18 | K18: 4645000 | L18: 36093900 | M18: =L18-N18 | N18: 7420800 | O18: 28291200 | P18: =O18-Q18 | Q18: 5770300 | R18: 11271200 | S18: =R18-T18 | T18: 2254200 | U18: 10345100 | V18: =U18-W18 | W18: 2072900 | X18: 8672400 | Y18: =X18-Z18 | Z18: 1736600 | AA18: 5015300 | AB18: =AA18-AC18 | AC18: 1012200 | AD18: 4570400 | AE18: =AD18-AF18 | AF18: 917100 | AG18: 1065200 | AH18: =AG18-AI18 | AI18: 225000 | AJ18: 6550500 | AK18: =AJ18-AL18 | AL18: 1317600 | AM18: 677 | AN18: 8786800 | AO18: =AN18-AP18 | AP18: 1790700 | AQ18: 570 | AR18: 5969500 | AS18: =AR18-AT18 | AT18: 1208800 | AU18: 1429 | AV18: 12594800 | AW18: =AV18-AX18 | AX18: 2577300 | AY18: 384 | AZ18: 3587200 | BA18: =AZ18-BB18 | BB18: 735300 | BC18: 387 | BD18: 4643400 | BE18: =BD18-BF18 | BF18: 969500 | BG18: 537 | BH18: 5927000 | BI18: =BH18-BJ18 | BJ18: 1225400 | BK18: 388 | BL18: 4345600 | BM18: =BL18-BN18 | BN18: 894400 | BO18: 8 | BP18: 117900 | BQ18: =BP18-BR18 | BR18: 22100 | BS18: 1 | BT18: 26400 | BU18: =BT18-BV18 | BV18: 4500 | BW18: 1 | BX18: 29000 | BY18: =BX18-BZ18 | BZ18: 7200 | CA18: 3 | CB18: 26400 | CC18: =CB18-CD18 | CD18: 4500 | CE18: 4 | CF18: 59100 | CG18: 44300 | CH18: =CF18-CG18 | CI18: 0 | CJ18: 0 | CK18: 0 | CL18: 0 | CM18: 0 | CN18: 0 | CO18: 0 | CP18: 0 | CQ18: 0
A19: Total Enterprise Client | C19: =SUM(C4:C18) | D19: =SUM(D4:D18) | E19: =SUM(E4:E18) | F19: =SUM(F4:F18) | G19: =SUM(G4:G18) | H19: =SUM(H4:H18) | I19: =SUM(I4:I18) | J19: =SUM(J4:J18) | ... CP19: =SUM(CP4:CP18) | CQ19: =(CM19-CE19)/CE19 | CR19: Overall decrease happen due to holiday seasons (1-4 Jan 2026)
A21: Medium, Small & Individual Client | C21: =C23-C19 | D21: =D23-D19 | E21: =E23-E19 | F21: =F23-F19 | G21: =G23-G19 | H21: =H23-H19 | I21: =I23-I19 | J21: =J23-J19 | ... AL21: =AL23-AL19 | AM21: 62217 | AN21: 993661187 | AO21: =AN21-AP21 | AP21: 205350647 | AQ21: 50539 | AR21: 783018538 | AS21: =AR21-AT21 | AT21: 158500601 | AU21: 70808 | AV21: 1245823828 | AW21: =AV21-AX21 | AX21: 254898170 | AY21: 40573 | AZ21: 617168994 | BA21: =AZ21-BB21 | BB21: 118599188 | BC21: 47055 | BD21: 728997153 | BE21: =BD21-BF21 | BF21: 143011358 | BG21: 41575 | BH21: 633640803 | BI21: =BH21-BJ21 | BJ21: 115834300 | BK21: 41134 | BL21: 618760064 | BM21: =BL21-BN21 | BN21: 121342357 | BO21: 39636 | BP21: 588752832 | BQ21: =BP21-BR21 | BR21: 111515895 | BS21: 42401 | BT21: 568549298 | BU21: =BT21-BV21 | BV21: 107057467 | BW21: 37773 | BX21: 558138371 | BY21: =BX21-BZ21 | BZ21: 68700394 | CA21: 33903 | CB21: 499639300 | CC21: =CB21-CD21 | CD21: 88143413 | CE21: 48812.001 | CF21: 914462200 | CG21: 725488032 | CH21: 188974168 | CI21: 10291 | CJ21: 164361500 | CK21: 127984712 | CL21: 36376788 | CM21: =CI21/11*31 | CN21: =CJ21/11*31 | CO21: =CK21/11*31 | CP21: =CL21/11*31 | CQ21: =(CM21-CE21)/CE21 | CR21: All seasonal client stop, and due to holiday the delivery was drop.
A23: Total All Client | C23: 3807990803 | D23: =C23-E23 | E23: 702459310 | F23: 2966616029 | G23: =F23-H23 | H23: 608325072 | I23: 3173934990 | J23: =I23-K23 | K23: 666409474 | L23: 2668582694 | M23: =L23-N23 | N23: 564829614 | O23: 2509612001 | P23: =O23-Q23 | Q23: 526990437 | R23: 2327159148 | S23: =R23-T23 | T23: 495756510 | U23: 2434013785 | V23: =U23-W23 | W23: 517401262 | X23: 2450441301 | Y23: =X23-Z23 | Z23: 504987061 | AA23: 2099269888 | AB23: =AA23-AC23 | AC23: 410650654 | AD23: 2150814901 | AE23: =AD23-AF23 | AF23: 422472642 | AG23: 1936730842 | AH23: =AG23-AI23 | AI23: 383864383 | AJ23: 2178422501 | AK23: =AJ23-AL23 | AL23: 449402949 | AM23: =AM21+AM19 | AN23: =AN21+AN19 | AO23: =AO21+AO19 | AP23: =AP21+AP19 | AQ23: =AQ21+AQ19 | AR23: =AR21+AR19 | AS23: =AS21+AS19 | AT23: =AT21+AT19 | ... CE23: =CE21+CE19 | CF23: =CF19+CF21 | CG23: =CG19+CG21 | CH23: =CH19+CH21 | CI23: =CI21+CI19 | CJ23: =CJ21+CJ19 | CK23: =CK21+CK19 | CL23: =CL21+CL19 | CM23: =CM21+CM19 | CN23: =CN21+CN19 | CO23: =CO21+CO19 | CP23: =CP21+CP19 | CQ23: =(CM23-CE23)/CE23
A24: % Gross Revenue | E24: =E23/C23 | H24: =H23/F23 | K24: =K23/I23 | N24: =N23/L23 | Q24: =Q23/O23 | T24: =T23/R23 | W24: =W23/U23 | Z24: =Z23/X23 | AC24: =AC23/AA23 | AF24: =AF23/AD23 | AI24: =AI23/AG23 | AL24: =AL23/AJ23 | AP24: =AP23/AN23 | AT24: =AT23/AR23 | AX24: =AX23/AV23 | BB24: =BB23/AZ23 | BF24: =BF23/BD23 | BJ24: =BJ23/BH23 | BN24: =BN23/BL23 | BR24: =BR23/BP23 | BV24: =BV23/BT23 | BZ24: =BZ23/BX23 | CD24: =CD23/CB23 | CH24: =CH23/CF23 | CL24: =CL23/CJ23 | CP24: =CP23/CN23
A29: % Enterprise Client | E29: =E19/E23 | H29: =H19/H23 | K29: =K19/K23 | N29: =N19/N23 | Q29: =Q19/Q23 | T29: =T19/T23 | W29: =W19/W23 | Z29: =Z19/Z23 | AC29: =AC19/AC23 | AF29: =AF19/AF23 | AI29: =AI19/AI23 | AL29: =AL19/AL23 | AP29: =AP19/AP23 | AT29: =AT19/AT23 | AX29: =AX19/AX23 | BB29: =BB19/BB23 | BF29: =BF19/BF23 | BJ29: =BJ19/BJ23 | BN29: =BN19/BN23 | BR29: =BR19/BR23 | BV29: =BV19/BV23 | BZ29: =BZ19/BZ23 | CD29: =CD19/CD23 | CH29: =CH19/CH23 | CL29: =CL19/CL23 | CP29: =CP19/CP23
A30: % Med, Small, Individual Client | E30: =E21/E23 | H30: =H21/H23 | K30: =K21/K23 | N30: =N21/N23 | Q30: =Q21/Q23 | T30: =T21/T23 | W30: =W21/W23 | Z30: =Z21/Z23 | AC30: =AC21/AC23 | AF30: =AF21/AF23 | AI30: =AI21/AI23 | AL30: =AL21/AL23 | AP30: =AP21/AP23 | AT30: =AT21/AT23 | AX30: =AX21/AX23 | BB30: =BB21/BB23 | BF30: =BF21/BF23 | BJ30: =BJ21/BJ23 | BN30: =BN21/BN23 | BR30: =BR21/BR23 | BV30: =BV21/BV23 | BZ30: =BZ21/BZ23 | CD30: =CD21/CD23 | CH30: =CH21/CH23 | CL30: =CL21/CL23 | CP30: =CP21/CP23
A33: Highlighted Seasonal Client
A34: 916899 | B34: Pandor | CE34: 1783 | CF34: 77914800 | CG34: 62354800 | CH34: =CF34-CG34
A35: 923635 | B35: Kibo | CE35: 1030 | CF35: 26149000 | CG35: 21135200 | CH35: =CF35-CG35
A36: 733016 | B36: Belin Bakery | CE36: =1835+418 | CF36: =42055400+5855900 | CG36: =33571700+4627000 | CH36: =CF36-CG36

Sheet Marketing PL Target
A1: Marketing Target PL (Using Tiktok PL)
A3: Description | B3: Jan'26 | C3: Feb'26 | D3: Mar'26 | E3: Apr'26 | F3: May'26 | G3: Jun'26 | H3: Jul'26 | I3: Aug'26 | J3: Sep'26 | K3: Oct'25 | L3: Nov'26 | M3: Des'26
A5: Deliveries
A6: - Before | B6: 72550 | C6: 91783 | D6: 121890 | E6: 112183 | F6: 118363 | G6: 124572 | H6: 130292 | I6: 136409 | J6: 142298 | K6: 148391 | L6: 164789 | M6: 201067
A7: - After | B7: 72550 | C7: 91783 | D7: 122790 | E7: 116973 | F7: 123296 | G7: 129653 | H7: 135526 | I7: 141800 | J7: 147851 | K7: 154110 | L7: 170680 | M7: 207548
A8: Diff | B8: =B7-B6 | C8: =C7-C6 | D8: =D7-D6 | E8: =E7-E6 | F8: =F7-F6 | G8: =G7-G6 | H8: =H7-H6 | I8: =I7-I6 | ... M8: =M7-M6
A10: GMV
A11: - Before | B11: 1197075000 | C11: 1284962000 | D11: 1767405000 | E11: 1458379000 | F11: 1538719000 | G11: 1619436000 | H11: 1693796000 | I11: 1773317000 | J11: 1849874000 | K11: 1929083000 | L11: 2142257000 | M11: 3317605500
A12: - After | B12: 1197075000 | C12: 1284962000 | D12: 1780455000 | E12: 1520649000 | F12: 1602848000 | G12: 1685489000 | H12: 1761838000 | I12: 1843400000 | J12: 1922063000 | K12: 2003430000 | L12: 2218840000 | M12: 3424542000
A13: Diff | B13: =B12-B11 | C13: =C12-C11 | D13: =D12-D11 | E13: =E12-E11 | F13: =F12-F11 | G13: =G12-G11 | H13: =H12-H11 | I13: =I12-I11 | ... M13: =M12-M11
A15: Couriers
A16: - Before | B16: 1650 | C16: =B16 | D16: =C16 | E16: =D16 | F16: =E16 | G16: =F16 | H16: =G16 | I16: =H16 | J16: =I16 | ... M16: =L16
A17: - After | B17: =B16+115 | C17: =B17+150 | D17: =C17+200 | E17: =D17+200 | F17: =E17+200 | G17: =F17+200 | H17: =G17+200 | I17: =H17+200 | J17: =I17+200 | K17: =J17+200 | ... M17: =L17+200
A18: Diff | B18: =B17-B16 | C18: =C17-C16 | D18: =D17-D16 | E18: =E17-E16 | F18: =F17-F16 | G18: =G17-G16 | H18: =H17-H16 | I18: =I17-I16 | ... M18: =M17-M16
A20: Average Deliveries Per Couriers | B20: =B7/B17 | C20: =C7/C17 | D20: =D7/D17 | E20: =E7/E17 | F20: =F7/F17 | G20: =G7/G17 | H20: =H7/H17 | I20: =I7/I17 | ... M20: =M7/M17
A23: Marketing Budget
A24: - Marketing Budget | B24: 5000000 | C24: 35000000 | D24: 35000000 | E24: 35000000 | F24: 35000000 | G24: 35000000 | H24: 35000000 | I24: 35000000 | J24: 35000000 | K24: 35000000 | L24: 35000000 | M24: 35000000
A25: - Salary team | B25: 4050000 | C25: 9900000 | D25: 9900000 | E25: 9900000 | F25: 9900000 | G25: 9900000 | H25: 9900000 | I25: 9900000 | J25: 9900000 | K25: 9900000 | L25: 9900000 | M25: 9900000
A26: Total | B26: =sum(B24:B25) | C26: =sum(C24:C25) | D26: =sum(D24:D25) | E26: =sum(E24:E25) | F26: =sum(F24:F25) | G26: =sum(G24:G25) | H26: =sum(H24:H25) | I26: =sum(I24:I25) | ... M26: =sum(M24:M25)
A28: PL Effect | B28: =B13-B26 | C28: =C13-C26 | D28: =D13-D26 | E28: =E13-E26 | F28: =F13-F26 | G28: =G13-G26 | H28: =H13-H26 | I28: =I13-I26 | ... M28: =M13-M26

Sheet 2026 Plan
A1: Slow Growing Projection
B2: % | C2: Jan'26 | D2: Feb'26 | E2: Mar'26 | F2: Apr'26 | G2: May'26 | H2: Jun'26 | I2: Jul'26 | J2: Aug'26 | K2: Sep'26 | L2: Oct'25 | M2: Nov'26 | N2: Des'26
A3: Deliveries | C3: ='Client Forecast'!B5 | D3: ='Client Forecast'!C5 | E3: ='Client Forecast'!D5 | F3: ='Client Forecast'!E5 | G3: ='Client Forecast'!F5 | H3: ='Client Forecast'!G5 | I3: ='Client Forecast'!H5 | J3: ='Client Forecast'!I5 | ... N3: ='Client Forecast'!M5
A4: ADV | C4: 16500 | D4: 18000 | E4: 18500 | F4: 16500 | G4: 16500 | H4: 16500 | I4: 16500 | J4: 16500 | K4: 16500 | L4: 16500 | M4: 16500 | N4: 19400
A6: GMV | C6: =C3*C4 | D6: =D3*D4 | E6: =E3*E4 | F6: =F3*F4 | G6: =G3*G4 | H6: =H3*H4 | I6: =I3*I4 | J6: =J3*J4 | ... N6: =N3*N4
A7: Couriers Cost | B7: 0.78 | C7: =C6*$B$7 | D7: =D6*$B$7 | E7: =E6*$B$7 | F7: =F6*$B$7 | G7: =G6*$B$7 | H7: =H6*$B$7 | I7: =I6*$B$7 | J7: =J6*$B$7 | ... N7: =N6*$B$7
D8: =(D6-C6)/C6 | E8: =(E6-D6)/D6 | F8: =(F6-E6)/E6 | G8: =(G6-F6)/F6 | H8: =(H6-G6)/G6 | I8: =(I6-H6)/H6 | J8: =(J6-I6)/I6 | K8: =(K6-J6)/J6 | ... N8: =(N6-M6)/M6
A9: Gross Margin | C9: =C6-C7 | D9: =D6-D7 | E9: =E6-E7 | F9: =F6-F7 | G9: =G6-G7 | H9: =H6-H7 | I9: =I6-I7 | J9: =J6-J7 | ... N9: =N6-N7
A11: OS Cost
A12: Bank Fee | B12: 0.004 | C12: =$B$12*C6 | D12: =$B$12*D6 | E12: =$B$12*E6 | F12: =$B$12*F6 | G12: =$B$12*G6 | H12: =$B$12*H6 | I12: =$B$12*I6 | J12: =$B$12*J6 | ... N12: =$B$12*N6
A13: Infrastructure + IT Support | B13: USD 14.070 | C13: =14070*16700 | D13: =14070*16700 | E13: =14070*16700 | F13: =14070*16700 | G13: =14070*16700 | H13: =14070*16700 | I13: =14070*16700 | J13: =14070*16700 | ... N13: =14070*16700
A14: Loss from fraud,incident | B14: 3e-06 | C14: =$B$14*C6 | D14: =$B$14*D6 | E14: =$B$14*E6 | F14: =$B$14*F6 | G14: =$B$14*G6 | H14: =$B$14*H6 | I14: =$B$14*I6 | J14: =$B$14*J6 | ... N14: =$B$14*N6
A15: Salary - OS team | C15: =82200000*118% | D15: =82200000*118% | E15: =82200000*118%*2 | F15: =82200000*118% | G15: =82200000*118% | H15: =82200000*118% | I15: =82200000*118% | J15: =82200000*118% | K15: =82200000*118% | L15: =82200000*118% | M15: =82200000*118% | N15: =82200000*118%
A16: Other OS cost | C16: =150000*27*3 | D16: =150000*27*3 | E16: =150000*27*3 | F16: =150000*27*3 | G16: =150000*27*3 | H16: =150000*27*3 | I16: =150000*27*3 | J16: =150000*27*3 | ... N16: =150000*27*3
A17: Total OS Cost | C17: =SUM(C12:C16) | D17: =SUM(D12:D16) | E17: =SUM(E12:E16) | F17: =SUM(F12:F16) | G17: =SUM(G12:G16) | H17: =SUM(H12:H16) | I17: =SUM(I12:I16) | J17: =SUM(J12:J16) | ... N17: =SUM(N12:N16)
A19: Margin After Operating | C19: =C9-C17 | D19: =D9-D17 | E19: =E9-E17 | F19: =F9-F17 | G19: =G9-G17 | H19: =H9-H17 | I19: =I9-I17 | J19: =J9-J17 | ... N19: =N9-N17
A21: Marketing Cost
A22: SEO, SEM, Etc | C22: 5000000 | D22: 35000000 | E22: 35000000 | F22: 35000000 | G22: 35000000 | H22: 35000000 | I22: 35000000 | J22: 35000000 | K22: 35000000 | L22: 35000000 | M22: 35000000 | N22: 35000000
A23: Soc Med Cost | C23: 1000000 | D23: 1000000 | E23: 1000000 | F23: 1000000 | G23: 1000000 | H23: 1000000 | I23: 1000000 | J23: 1000000 | K23: 1000000 | L23: 1000000 | M23: 1000000 | N23: 1000000
A24: Printing Product | C24: 0 | D24: 0 | E24: 0 | F24: 0 | G24: 0 | H24: 0 | I24: 0 | J24: 0 | K24: 0 | L24: 0 | M24: 0 | N24: 0
A25: Marketing Salary | C25: =9000000*110%*9/22 | D25: =9000000*110% | E25: =9000000*110% | F25: =9000000*110% | G25: =9000000*110% | H25: =9000000*110% | I25: =9000000*110% | J25: =9000000*110% | K25: =9000000*110% | ... N25: =9000000*110%
A26: Total Marketing Cost | C26: =SUM(C22:C25) | D26: =SUM(D22:D25) | E26: =SUM(E22:E25) | F26: =SUM(F22:F25) | G26: =SUM(G22:G25) | H26: =SUM(H22:H25) | I26: =SUM(I22:I25) | J26: =SUM(J22:J25) | ... N26: =SUM(N22:N25)
A28: GA Cost
A29: Audit & Consulting Services | C29: 1800000 | D29: 1800000 | E29: 1800000 | F29: 3600000 | G29: 1800000 | H29: 1800000 | I29: 1800000 | J29: 1800000 | K29: 1800000 | L29: 1800000 | M29: 1800000 | N29: 1800000
A30: Communication Expenses | C30: 500000 | D30: 500000 | E30: 0 | F30: 0 | G30: 0 | H30: 0 | I30: 0 | J30: 0 | K30: 0 | L30: 0 | M30: 0 | N30: 0
A31: Insurance | C31: 0 | D31: 0 | E31: 0 | F31: 0 | G31: 0 | H31: 0 | I31: 0 | J31: 0 | K31: 0 | L31: 0 | M31: 0 | N31: 0
A32: IT Supply | C32: 200000 | D32: 200000 | E32: 200000 | F32: 200000 | G32: 200000 | H32: 200000 | I32: 200000 | J32: 200000 | K32: 200000 | L32: 200000 | M32: 200000 | N32: 200000
A33: Legal Services | C33: 0 | D33: 0 | E33: 0 | F33: 0 | G33: 0 | H33: 0 | I33: 0 | J33: 0 | K33: 0 | L33: 0 | M33: 0 | N33: 0
A34: Office Expenses | C34: =300000+2200000+700000+500000+800000+500000 | D34: =300000+2200000+700000+500000+800000+500000 | E34: =300000+2200000+700000+500000+800000+500000 | F34: =300000+2200000+700000+500000+800000+500000 | G34: =300000+2200000+700000+500000+800000+500000 | H34: =300000+2200000+700000+500000+800000+500000 | I34: =300000+2200000+700000+500000+800000+500000 | J34: =300000+2200000+700000+500000+800000+500000 | ... N34: =300000+2200000+700000+500000+800000+500000
A35: Travel Expenses | C35: 2000000 | D35: 2000000 | E35: 2000000 | F35: 2000000 | G35: 2000000 | H35: 2000000 | I35: 2000000 | J35: 2000000 | K35: 2000000 | L35: 2000000 | M35: 2000000 | N35: 2000000
A36: Salary GA | C36: =114425000*118% | D36: =114425000*118% | E36: =114425000*118%*2-25400000 | F36: =114425000*118% | G36: =114425000*118% | H36: =114425000*118% | I36: =114425000*118% | J36: =114425000*118% | K36: =114425000*118% | L36: =114425000*118% | M36: =114425000*118% | N36: =114425000*118%+25400000
A37: Other GA Cost | C37: 1000000 | D37: 1000000 | E37: 1000000 | F37: 1000000 | G37: 1000000 | H37: 1000000 | I37: 1000000 | J37: 1000000 | K37: 1000000 | L37: 1000000 | M37: 1000000 | N37: 1000000
A38: Total GA Cost | C38: =SUM(C29:C37) | D38: =SUM(D29:D37) | E38: =SUM(E29:E37) | F38: =SUM(F29:F37) | G38: =SUM(G29:G37) | H38: =SUM(H29:H37) | I38: =SUM(I29:I37) | J38: =SUM(J29:J37) | ... N38: =SUM(N29:N37)
A40: PL Before Tax | C40: =C19-C26-C38 | D40: =D19-D26-D38 | E40: =E19-E26-E38 | F40: =F19-F26-F38 | G40: =G19-G26-G38 | H40: =H19-H26-H38 | I40: =I19-I26-I38 | J40: =J19-J26-J38 | ... N40: =N19-N26-N38
A42: Taxes
A43: - WHT 23 | C43: =C6*60%*2% | D43: =D6*60%*2% | E43: =E6*60%*2% | F43: =F6*60%*2% | G43: =G6*60%*2% | H43: =H6*60%*2% | I43: =I6*60%*2% | J43: =J6*60%*2% | ... N43: =N6*60%*2%
A44: - Tax Income | C44: 0 | D44: 0 | E44: 0 | F44: 0 | G44: 0 | H44: 0 | I44: 0 | J44: 0 | K44: 0 | L44: 0 | M44: 0 | N44: =IF(SUM(C40:N40)<=0,0,SUM(C40:N40)*22%)
A45: Total Tax | C45: =SUM(C43:C44) | D45: =SUM(D43:D44) | E45: =SUM(E43:E44) | F45: =SUM(F43:F44) | G45: =SUM(G43:G44) | H45: =SUM(H43:H44) | I45: =SUM(I43:I44) | J45: =SUM(J43:J44) | ... N45: =SUM(N43:N44)
A47: PL After Tax | C47: =C40-C45 | D47: =D40-D45 | E47: =E40-E45 | F47: =F40-F45 | G47: =G40-G45 | H47: =H40-H45 | I47: =I40-I45 | J47: =J40-J45 | ... N47: =N40-N45 | O47: =SUM(C47:N47)
A49: Without Infrastructure
...

Sheet Client Forecast
A1: Forecast 2026 No Growth
B4: 46048 | C4: 46079 | D4: 46107 | E4: 46138 | F4: 46168 | G4: 46199 | H4: 46229 | I4: 46260 | J4: 46291 | K4: 46321 | L4: 46352 | M4: 46382
A5: Total Delivery | B5: =B6+B8 | C5: =C6+C8 | D5: =D6+D8 | E5: =E6+E8 | F5: =F6+F8 | G5: =G6+G8 | H5: =H6+H8 | I5: =I6+I8 | ... M5: =M6+M8
A6: Organic | B6: 25000 | C6: 25750 | D6: =30900+5000 | E6: 31827 | F6: 32781 | G6: 33765 | H6: 34778 | I6: 35821 | J6: 36896 | K6: 38003 | L6: 39143 | M6: =43057+5000
A8: Total | B8: =SUM(B10:B51) | C8: =SUM(C10:C31) | D8: =SUM(D10:D51) | E8: =SUM(E10:E51) | F8: =SUM(F10:F51) | G8: =SUM(G10:G51) | H8: =SUM(H10:H51) | I8: =SUM(I10:I51) | J8: =SUM(J10:J51) | K8: =SUM(K10:K51) | ... M8: =SUM(M10:M51)
A10: Nuskin invoice | B10: 1900 | C10: 1793 | D10: 2000 | E10: 1756 | F10: 2025 | G10: 2198 | H10: 1858 | I10: 1789 | J10: 1565 | K10: 1417 | L10: 1547 | M10: 2000
A11: mClinica Akun Utama | B11: 1500 | C11: 1500 | D11: 1500 | E11: 1500 | F11: 1500 | G11: 1500 | H11: 1500 | I11: 1500 | J11: 1500 | K11: 1500 | L11: 1500 | M11: 1500
A12: PT. Cipta Dwiputra Cemerlang | B12: 2500
A13: Grouu Baby | B13: 2300 | C13: 2200 | D13: 2200 | E13: 2200 | F13: 2200 | G13: 2200 | H13: 2200 | I13: 2200 | J13: 2200 | K13: 2200 | L13: 2200 | M13: 2200
A14: Super Grain | B14: 1000 | C14: 1000 | D14: 1000 | E14: 1000 | F14: 1000 | G14: 1000 | H14: 1000 | I14: 1000 | J14: 1000 | K14: 1000 | L14: 1000 | M14: 1000
A15: Lazada Indonesia Invoice | B15: 1000 | C15: 1000 | D15: 1000 | E15: 1000 | F15: 1000 | G15: 1000 | H15: 1000 | I15: 1000 | J15: 1000 | K15: 1000 | L15: 1000 | M15: 1000
A16: Andalan Express Indonesia | B16: 2700 | C16: 2700 | D16: 2700 | E16: 2700 | F16: 2700 | G16: 2700 | H16: 2700 | I16: 2700 | J16: 2700 | K16: 2700 | L16: 2700 | M16: 2700
A17: Halodoc Indonesia | B17: 15000 | C17: 20000 | D17: 30000 | E17: 30000 | F17: 30000 | G17: 30000 | H17: 30000 | I17: 30000 | J17: 30000 | K17: 30000 | L17: 30000 | M17: 30000
A18: Klean Katering Invoice | B18: 5500 | C18: 5500 | D18: 5500 | E18: 5500 | F18: 5500 | G18: 5500 | H18: 5500 | I18: 5500 | J18: 5500 | K18: 5500 | L18: 5500 | M18: 5500
A19: Alpro | B19: 2500 | C19: 2000 | D19: 2000 | E19: 2000 | F19: 2000 | G19: 2000 | H19: 2000 | I19: 2000 | J19: 2000 | K19: 2000 | L19: 2000 | M19: 2000
A20: DHL | B20: 2000 | C20: 2000 | D20: 2000 | E20: 2000 | F20: 2000 | G20: 2000 | H20: 2000 | I20: 2000 | J20: 2000 | K20: 2000 | L20: 2000 | M20: 2000
A21: DSV | B21: 4850 | C21: 4850 | D21: 4850 | E21: 4850 | F21: 4850 | G21: 4850 | H21: 4850 | I21: 4850 | J21: 4850 | K21: 4850 | L21: 4850 | M21: 4850
A22: SSN | B22: 600 | C22: 600 | D22: 600 | E22: 600 | F22: 600 | G22: 600 | H22: 600 | I22: 600 | J22: 600 | K22: 600 | L22: 600 | M22: 600
A23: Cokro | B23: 1300 | C23: 1300 | D23: 1300 | E23: 1300 | F23: 1300 | G23: 1300 | H23: 1300 | I23: 1300 | J23: 1300 | K23: 1300 | L23: 1300 | M23: 1300
A24: Selectro | B24: 1000 | C24: 1000 | D24: 1000 | E24: 1000 | F24: 1000 | G24: 1000 | H24: 1000 | I24: 1000 | J24: 1000 | K24: 1000 | L24: 1000 | M24: 1000
A26: Seasonal
A27: Pandor | C27: 1000 | D27: 1800 | M27: 2000
A28: KiboChese | C28: 500 | D28: 1200 | M28: 1500
A29: Bellin Bakery Jakarta | C29: 500 | D29: 2000 | M29: 2000
A30: Bellin Bakery Surabaya | C30: 500 | D30: 1000 | M30: 1000
A31: Exquise | C31: 100 | D31: 1000 | M31: 1000
A35: New Client
A36: Alofresh | B36: 500 | C36: 500 | D36: 500 | E36: 500 | F36: 500 | G36: 500 | H36: 700 | I36: 1000 | J36: 1200 | K36: 1500 | L36: 1500 | M36: 1500
A37: Aido | B37: 1000 | C37: 3000 | D37: 3000 | E37: 3000 | F37: 3000 | G37: 3000 | H37: 3000 | I37: 3000 | J37: 3000 | K37: 3000 | L37: 3000 | M37: 3000
A38: Sodexo | B38: 0 | C38: 300 | D38: 500 | E38: 900 | F38: 900 | G38: 900 | H38: 900 | I38: 900 | J38: 900 | K38: 900 | L38: 900 | M38: 900
A39: Camilla La Mozzarella | B39: 0 | C39: 500 | D39: 500 | E39: 500 | F39: 500 | G39: 500 | H39: 500 | I39: 500 | J39: 500 | K39: 500 | L39: 500 | M39: 500
A40: dapoer seodjutarasa | B40: 0 | C40: 300 | D40: 300 | E40: 300 | F40: 300 | G40: 300 | H40: 300 | I40: 300 | J40: 300 | K40: 300 | L40: 300 | M40: 300
A41: SGL | B41: 300 | C41: 300 | D41: 300 | E41: 300 | F41: 300 | G41: 300 | H41: 300 | I41: 300 | J41: 300 | K41: 300 | L41: 300 | M41: 300
A42: Kebun Malika | B42: 0 | C42: 500 | D42: 500 | E42: 500 | F42: 500 | G42: 500 | H42: 500 | I42: 500 | J42: 500 | K42: 500 | L42: 500 | M42: 500
A43: Point Laundry | B43: 100 | C43: 150 | D43: 200 | E43: 200 | F43: 200 | G43: 200 | H43: 200 | I43: 200 | J43: 200 | K43: 200 | L43: 500 | M43: 500
A44: Modena | C44: 300 | D44: 300 | E44: 300 | F44: 300 | G44: 300 | H44: 300 | I44: 300 | J44: 300 | K44: 300 | L44: 300 | M44: 300
A45: Insecta | C45: 300 | D45: 300 | E45: 300 | F45: 300 | G45: 300 | H45: 300 | I45: 300 | J45: 300 | K45: 300 | L45: 300 | M45: 300
A46: VOdjo - Total buah | C46: 440 | D46: 440 | E46: 440 | F46: 440 | G46: 440 | H46: 440 | I46: 440 | J46: 440 | K46: 440 | L46: 440 | M46: 440
A47: ESB - Esensi Buana Solusi | C47: 300 | D47: 300 | E47: 300 | F47: 300 | G47: 300 | H47: 300 | I47: 300 | J47: 300 | K47: 300 | L47: 300 | M47: 300
A48: Klinik Pertamina IHC | C48: 100 | D48: 100 | E48: 200 | F48: 300 | G48: 500 | H48: 500 | I48: 500 | J48: 500 | K48: 500 | L48: 500 | M48: 500
...

Sheet Sheet5
E4: 1st order | F4: next order | G4: next order | H4: next order
D5: Blitz Cost | E5: 16000 | F5: 16000 | G5: 16000 | H5: 16000
E6: 9000 | F6: 9000 | G6: 9000 | H6: 9000
D7: Blitz Margin | E7: 360 | F7: 360 | G7: 360 | H7: 360
D8: Borzo | E8: 9000 | F8: 3200 | G8: 3200 | H8: 3200
D9: Borzo margin | E9: 1000 | F9: 800 | G9: 800 | H9: 800
